Failure # 1 (occurred at 2023-03-29_10-25-03)
Traceback (most recent call last):
  File "C:\Users\joeku\anaconda3\envs\overcooked_ai\lib\site-packages\ray\tune\execution\ray_trial_executor.py", line 989, in get_next_executor_event
    future_result = ray.get(ready_future)
  File "C:\Users\joeku\anaconda3\envs\overcooked_ai\lib\site-packages\ray\_private\client_mode_hook.py", line 105, in wrapper
    return func(*args, **kwargs)
  File "C:\Users\joeku\anaconda3\envs\overcooked_ai\lib\site-packages\ray\_private\worker.py", line 2277, in get
    raise value
ray.exceptions.RayActorError: The actor died because of an error raised in its creation task, [36mray::PPO.__init__()[39m (pid=43040, ip=127.0.0.1, repr=PPO)
  File "C:\Users\joeku\anaconda3\envs\overcooked_ai\lib\site-packages\ray\rllib\evaluation\worker_set.py", line 127, in __init__
    validate=trainer_config.get("validate_workers_after_construction"),
  File "C:\Users\joeku\anaconda3\envs\overcooked_ai\lib\site-packages\ray\rllib\evaluation\worker_set.py", line 269, in add_workers
    self.foreach_worker(lambda w: w.assert_healthy())
  File "C:\Users\joeku\anaconda3\envs\overcooked_ai\lib\site-packages\ray\rllib\evaluation\worker_set.py", line 391, in foreach_worker
    remote_results = ray.get([w.apply.remote(func) for w in self.remote_workers()])
  File "C:\Users\joeku\anaconda3\envs\overcooked_ai\lib\site-packages\ray\_private\client_mode_hook.py", line 105, in wrapper
    return func(*args, **kwargs)
  File "C:\Users\joeku\anaconda3\envs\overcooked_ai\lib\site-packages\ray\_private\worker.py", line 2277, in get
    raise value
ray.exceptions.RayActorError: The actor died because of an error raised in its creation task, [36mray::RolloutWorker.__init__()[39m (pid=43220, ip=127.0.0.1, repr=<ray.rllib.evaluation.rollout_worker.RolloutWorker object at 0x000001CA2C78BEC8>)
  File "python\ray\_raylet.pyx", line 662, in ray._raylet.execute_task
  File "python\ray\_raylet.pyx", line 666, in ray._raylet.execute_task
  File "python\ray\_raylet.pyx", line 613, in ray._raylet.execute_task.function_executor
  File "C:\Users\joeku\anaconda3\envs\overcooked_ai\lib\site-packages\ray\_private\function_manager.py", line 674, in actor_method_executor
    return method(__ray_actor, *args, **kwargs)
  File "C:\Users\joeku\anaconda3\envs\overcooked_ai\lib\site-packages\ray\util\tracing\tracing_helper.py", line 466, in _resume_span
    return method(self, *_args, **_kwargs)
  File "C:\Users\joeku\anaconda3\envs\overcooked_ai\lib\site-packages\ray\rllib\evaluation\rollout_worker.py", line 556, in __init__
    policy_spec, self.env, spaces=self.spaces, policy_config=policy_config
  File "C:\Users\joeku\anaconda3\envs\overcooked_ai\lib\site-packages\ray\rllib\evaluation\rollout_worker.py", line 1996, in _determine_spaces_for_multi_agent_dict
    "`observation_space` not provided in PolicySpec for "
ValueError: `observation_space` not provided in PolicySpec for default_policy and env does not have an observation space OR no spaces received from other workers' env(s) OR no `observation_space` specified in config!

During handling of the above exception, another exception occurred:

[36mray::PPO.__init__()[39m (pid=43040, ip=127.0.0.1, repr=PPO)
  File "python\ray\_raylet.pyx", line 655, in ray._raylet.execute_task
  File "python\ray\_raylet.pyx", line 696, in ray._raylet.execute_task
  File "python\ray\_raylet.pyx", line 662, in ray._raylet.execute_task
  File "python\ray\_raylet.pyx", line 666, in ray._raylet.execute_task
  File "python\ray\_raylet.pyx", line 613, in ray._raylet.execute_task.function_executor
  File "C:\Users\joeku\anaconda3\envs\overcooked_ai\lib\site-packages\ray\_private\function_manager.py", line 674, in actor_method_executor
    return method(__ray_actor, *args, **kwargs)
  File "C:\Users\joeku\anaconda3\envs\overcooked_ai\lib\site-packages\ray\util\tracing\tracing_helper.py", line 466, in _resume_span
    return method(self, *_args, **_kwargs)
  File "C:\Users\joeku\anaconda3\envs\overcooked_ai\lib\site-packages\ray\rllib\algorithms\algorithm.py", line 308, in __init__
    super().__init__(config=config, logger_creator=logger_creator, **kwargs)
  File "C:\Users\joeku\anaconda3\envs\overcooked_ai\lib\site-packages\ray\tune\trainable\trainable.py", line 157, in __init__
    self.setup(copy.deepcopy(self.config))
  File "C:\Users\joeku\anaconda3\envs\overcooked_ai\lib\site-packages\ray\util\tracing\tracing_helper.py", line 466, in _resume_span
    return method(self, *_args, **_kwargs)
  File "C:\Users\joeku\anaconda3\envs\overcooked_ai\lib\site-packages\ray\rllib\algorithms\algorithm.py", line 443, in setup
    raise e.args[0].args[2]
ValueError: `observation_space` not provided in PolicySpec for default_policy and env does not have an observation space OR no spaces received from other workers' env(s) OR no `observation_space` specified in config!

